Workbook

Sheet Assumptions
A1: ANDRO PRIME — PHASE 0 FINANCIAL MODEL
A2: Non-Regulated Tier | Updated with Vitall Lab Pricing | April 2026
A4: LAB COGS (Vitall — Finger-Prick)
B5: COGS (Vitall) | C5: Retail Price | D5: Gross Margin £ | E5: Gross Margin %
A6: Kit 1 — Hormone Check | B6: 58.5 | C6: 89 | D6: =C6-B6 -> 30.5 | E6: =D6/C6 -> 0.34269663
A7: Kit 2 — Energy & Metabolism | B7: 63 | C7: 99 | D7: =C7-B7 -> 36 | E7: =D7/C7 -> 0.36363636
A8: Kit 3 — Combo Test | B8: 98 | C8: 149 | D8: =C8-B8 -> 51 | E8: =D8/C8 -> 0.34228188
A10: SUPPLEMENT UNIT ECONOMICS (Market Research Est.)
B11: COGS (Est.) | C11: Sub Price /mo | D11: Gross Margin £ | E11: Gross Margin %
A12: Daily Stack | B12: 15 | C12: 34.95 | D12: =C12-B12 -> 19.95 | E12: =D12/C12 -> 0.57081545
A13: Joint & Recovery Collagen | B13: 13 | C13: 29.95 | D13: =C13-B13 -> 16.95 | E13: =D13/C13 -> 0.56594324
A14: Complete Stack (Bundle) | B14: =B12+B13 -> 28 | C14: 54.95 | D14: =C14-B14 -> 26.95 | E14: =D14/C14 -> 0.49044586
A16: KEY PLANNING ASSUMPTIONS
A17: Assumption | B17: Value | C17: Notes
A18: Payment processing (Stripe) | B18: 0.025 | C18: Applied to all revenue
A19: Affiliate commission rate | B19: 0.2 | C19: 20% on affiliate-driven sales
A20: Affiliate mix (% of kit sales) | B20: 0.3 | C20: Target from marketing plan
A21: Kit-to-supplement conversion | B21: 0.12 | C21: 12% planning case (V7.1 range: 10-15%)
A22: Supplement monthly churn | B22: 0.03 | C22: 3% monthly (marketing plan target)
A23: Founding member deposits | B23: 75 | C23: £75 per deposit
A24: Low-T rate (Kit 1 + Kit 3 buyers) | B24: 0.35 | C24: 35% of testosterone-tested men
A25: Deposit conversion (of low-T results) | B25: 0.5 | C25: 50% of low-T results deposit
A27: MARGIN IMPACT ANALYSIS
B28: Kit 1 | C28: Kit 2 | D28: Kit 3
A29: Retail Price | B29: =C6 -> 89 | C29: =C7 -> 99 | D29: =C8 -> 149
A30: COGS | B30: =B6 -> 58.5 | C30: =B7 -> 63 | D30: =B8 -> 98
A31: Gross Margin | B31: =B29-B30 -> 30.5 | C31: =C29-C30 -> 36 | D31: =D29-D30 -> 51
A32: Gross Margin % | B32: =B31/B29 -> 0.34269663 | C32: =C31/C29 -> 0.36363636 | D32: =D31/D29 -> 0.34228188
A33: Less: Payment Processing (2.5%) | B33: =B29*$B$18 -> 2.225 | C33: =C29*$B$18 -> 2.475 | D33: =D29*$B$18 -> 3.725
A34: Net Direct Margin | B34: =B31-B33 -> 28.275 | C34: =C31-C33 -> 33.525 | D34: =D31-D33 -> 47.275
A35: Net Direct Margin % | B35: =B34/B29 -> 0.31769663 | C35: =C34/C29 -> 0.33863636 | D35: =D34/D29 -> 0.31728188
A37: Less: Affiliate Commission (20%) | B37: =B29*$B$19 -> 17.8 | C37: =C29*$B$19 -> 19.8 | D37: =D29*$B$19 -> 29.8
A38: Net Affiliate Margin | B38: =B31-B33-B37 -> 10.475 | C38: =C31-C33-C37 -> 13.725 | D38: =D31-D33-D37 -> 17.475
A39: Net Affiliate Margin % | B39: =B38/B29 -> 0.11769663 | C39: =C38/C29 -> 0.13863636 | D39: =D38/D29 -> 0.11728188
A41: Blended Margin (30% affiliate mix) | B41: =(1-$B$20)*B34+$B$20*B38 -> 22.935 | C41: =(1-$B$20)*C34+$B$20*C38 -> 27.585 | D41: =(1-$B$20)*D34+$B$20*D38 -> 38.335
A42: Blended Margin % | B42: =B41/B29 -> 0.25769663 | C42: =C41/C29 -> 0.27863636 | D42: =D41/D29 -> 0.25728188

Sheet Operating Costs
A1: MONTHLY OPERATING COSTS — PHASE 0
A2: Excludes COGS, paid media, and affiliate commissions (modelled separately)
A4: Cost Item | B4: Monthly £ | C4: Notes
A5: PLATFORM & SOFTWARE
A6: Website hosting (Vercel/similar) | B6: 25 | C6: Free tier initially, scales to ~£25
A7: Domain & SSL | B7: 5 | C7: ~£60/year
A8: Email/CRM — Customer.io | B8: 200 | C8: Essentials plan for <1k contacts
A9: Design tools (Canva Pro) | B9: 13 | C9: £155/year
A10: Analytics (GA4 + Hotjar free) | B10: 0 | C10: Free tiers
A12: FINANCE & LEGAL
A13: Bookkeeping / accountant | B13: 200 | C13: Monthly retainer — basic Ltd accounts
A14: Payment processing (Stripe) | C14: Modelled as 2.5% of revenue in P&L
A15: Company insurance (product liability) | B15: 75 | C15: ~£900/year for supplement + wellness products
A17: OPERATIONS
A18: Customer support tools (Zendesk/Crisp) | B18: 30 | C18: Starter plan
A19: Phone/comms | B19: 30 | C19: Business mobile + VoIP
A20: Postage/misc fulfilment overhead | B20: 50 | C20: Returns, replacements, failed samples
A22: COMPLIANCE & REGULATORY
A23: FSA / label compliance review | B23: 42 | C23: ~£500/year — periodic review
A24: Data protection (ICO fee) | B24: 3 | C24: £35/year Tier 1
A26: FOUNDER COST (optional — opportunity cost)
A27: Keith time (not cash, but track it) | B27: 0 | C27: Unpaid initially — track hours for true cost
A29: TOTAL MONTHLY FIXED OVERHEAD | B29: =B6+B7+B8+B9+B10+B13+B15+B18+B19+B20+B23+B24+B27 -> 673
A31: ANNUAL EQUIVALENT | B31: =B29*12 -> 8076

Sheet 6-Month P&L
A1: PHASE 0 — 6-MONTH PROFIT & LOSS
A2: Planning Case | Finger-Prick Kits | Vitall Lab Partner
B4: Month 1 | C4: Month 2 | D4: Month 3 | E4: Month 4 | F4: Month 5 | G4: Month 6 | H4: 6-Mo Total
A5: KIT SALES VOLUME
A6: Kit 1 — Hormone Check | B6: 8 | C6: 12 | D6: 18 | E6: 22 | F6: 25 | G6: 30 | H6: =SUM(B6:G6) -> 115
A7: Kit 2 — Energy & Metabolism | B7: 15 | C7: 22 | D7: 30 | E7: 35 | F7: 40 | G7: 45 | H7: =SUM(B7:G7) -> 187
A8: Kit 3 — Combo Test | B8: 0 | C8: 5 | D8: 8 | E8: 12 | F8: 15 | G8: 18 | H8: =SUM(B8:G8) -> 58
A9: Total Kits Sold | B9: =SUM(B6:B8) -> 23 | C9: =SUM(C6:C8) -> 39 | D9: =SUM(D6:D8) -> 56 | E9: =SUM(E6:E8) -> 69 | F9: =SUM(F6:F8) -> 80 | G9: =SUM(G6:G8) -> 93 | H9: =SUM(H6:H8) -> 360
A10: Cumulative Kits | B10: =B9 -> 23 | C10: =B10+C9 -> 62 | D10: =C10+D9 -> 118 | E10: =D10+E9 -> 187 | F10: =E10+F9 -> 267 | G10: =F10+G9 -> 360 | H10: =G10 -> 360
A12: KIT REVENUE
A13: Kit 1 Revenue | B13: =B6*Assumptions!C6 -> 712 | C13: =C6*Assumptions!C6 -> 1068 | D13: =D6*Assumptions!C6 -> 1602 | E13: =E6*Assumptions!C6 -> 1958 | F13: =F6*Assumptions!C6 -> 2225 | G13: =G6*Assumptions!C6 -> 2670 | H13: =SUM(B13:G13) -> 10235
A14: Kit 2 Revenue | B14: =B7*Assumptions!C7 -> 1485 | C14: =C7*Assumptions!C7 -> 2178 | D14: =D7*Assumptions!C7 -> 2970 | E14: =E7*Assumptions!C7 -> 3465 | F14: =F7*Assumptions!C7 -> 3960 | G14: =G7*Assumptions!C7 -> 4455 | H14: =SUM(B14:G14) -> 18513
A15: Kit 3 Revenue | B15: =B8*Assumptions!C8 -> 0 | C15: =C8*Assumptions!C8 -> 745 | D15: =D8*Assumptions!C8 -> 1192 | E15: =E8*Assumptions!C8 -> 1788 | F15: =F8*Assumptions!C8 -> 2235 | G15: =G8*Assumptions!C8 -> 2682 | H15: =SUM(B15:G15) -> 8642
A16: Total Kit Revenue | B16: =SUM(B13:B15) -> 2197 | C16: =SUM(C13:C15) -> 3991 | D16: =SUM(D13:D15) -> 5764 | E16: =SUM(E13:E15) -> 7211 | F16: =SUM(F13:F15) -> 8420 | G16: =SUM(G13:G15) -> 9807 | H16: =SUM(H13:H15) -> 37390
A18: KIT COGS
A19: Kit 1 COGS | B19: =B6*Assumptions!B6 -> 468 | C19: =C6*Assumptions!B6 -> 702 | D19: =D6*Assumptions!B6 -> 1053 | E19: =E6*Assumptions!B6 -> 1287 | F19: =F6*Assumptions!B6 -> 1462.5 | G19: =G6*Assumptions!B6 -> 1755 | H19: =SUM(B19:G19) -> 6727.5
A20: Kit 2 COGS | B20: =B7*Assumptions!B7 -> 945 | C20: =C7*Assumptions!B7 -> 1386 | D20: =D7*Assumptions!B7 -> 1890 | E20: =E7*Assumptions!B7 -> 2205 | F20: =F7*Assumptions!B7 -> 2520 | G20: =G7*Assumptions!B7 -> 2835 | H20: =SUM(B20:G20) -> 11781
A21: Kit 3 COGS | B21: =B8*Assumptions!B8 -> 0 | C21: =C8*Assumptions!B8 -> 490 | D21: =D8*Assumptions!B8 -> 784 | E21: =E8*Assumptions!B8 -> 1176 | F21: =F8*Assumptions!B8 -> 1470 | G21: =G8*Assumptions!B8 -> 1764 | H21: =SUM(B21:G21) -> 5684
A22: Total Kit COGS | B22: =SUM(B19:B21) -> 1413 | C22: =SUM(C19:C21) -> 2578 | D22: =SUM(D19:D21) -> 3727 | E22: =SUM(E19:E21) -> 4668 | F22: =SUM(F19:F21) -> 5452.5 | G22: =SUM(G19:G21) -> 6354 | H22: =SUM(H19:H21) -> 24192.5
A24: Kit Gross Profit | B24: =B16-B22 -> 784 | C24: =C16-C22 -> 1413 | D24: =D16-D22 -> 2037 | E24: =E16-E22 -> 2543 | F24: =F16-F22 -> 2967.5 | G24: =G16-G22 -> 3453 | H24: =H16-H22 -> 13197.5
A25: Kit Gross Margin % | B25: =IF(B16=0,0,B24/B16) -> 0.35685025 | C25: =IF(C16=0,0,C24/C16) -> 0.3540466 | D25: =IF(D16=0,0,D24/D16) -> 0.35340042 | E25: =IF(E16=0,0,E24/E16) -> 0.35265566 | F25: =IF(F16=0,0,F24/F16) -> 0.35243468 | G25: =IF(G16=0,0,G24/G16) -> 0.35209544 | H25: =IF(H16=0,0,H24/H16) -> 0.35296871
A27: SUPPLEMENT SUBSCRIBERS
A28: New subscribers (from kit conversion) | B28: =ROUND((B7+B8)*Assumptions!B21,0) -> 2 | C28: =ROUND((C7+C8)*Assumptions!B21,0) -> 3 | D28: =ROUND((D7+D8)*Assumptions!B21,0) -> 5 | E28: =ROUND((E7+E8)*Assumptions!B21,0) -> 6 | F28: =ROUND((F7+F8)*Assumptions!B21,0) -> 7 | G28: =ROUND((G7+G8)*Assumptions!B21,0) -> 8 | H28: =SUM(B28:G28) -> 31
A29: Churned subscribers | B29: 0 | C29: =ROUND(B30*Assumptions!B22,0) -> 0 | D29: =ROUND(C30*Assumptions!B22,0) -> 0 | E29: =ROUND(D30*Assumptions!B22,0) -> 0 | F29: =ROUND(E30*Assumptions!B22,0) -> 0 | G29: =ROUND(F30*Assumptions!B22,0) -> 1 | H29: =SUM(B29:G29) -> 1
A30: Active Subscribers (end of month) | B30: =B28-B29 -> 2 | C30: =B30+C28-C29 -> 5 | D30: =C30+D28-D29 -> 10 | E30: =D30+E28-E29 -> 16 | F30: =E30+F28-F29 -> 23 | G30: =F30+G28-G29 -> 30 | H30: =G30 -> 30
A32: SUPPLEMENT FINANCIALS
A33: Supplement Revenue | B33: =B30*Assumptions!C12 -> 69.9 | C33: =C30*Assumptions!C12 -> 174.75 | D33: =D30*Assumptions!C12 -> 349.5 | E33: =E30*Assumptions!C12 -> 559.2 | F33: =F30*Assumptions!C12 -> 803.85 | G33: =G30*Assumptions!C12 -> 1048.5 | H33: =SUM(B33:G33) -> 3005.7
A34: Supplement COGS | B34: =B30*Assumptions!B12 -> 30 | C34: =C30*Assumptions!B12 -> 75 | D34: =D30*Assumptions!B12 -> 150 | E34: =E30*Assumptions!B12 -> 240 | F34: =F30*Assumptions!B12 -> 345 | G34: =G30*Assumptions!B12 -> 450 | H34: =SUM(B34:G34) -> 1290
A35: Supplement Gross Profit | B35: =B33-B34 -> 39.9 | C35: =C33-C34 -> 99.75 | D35: =D33-D34 -> 199.5 | E35: =E33-E34 -> 319.2 | F35: =F33-F34 -> 458.85 | G35: =G33-G34 -> 598.5 | H35: =H33-H34 -> 1715.7
A37: FOUNDING MEMBER DEPOSITS
A38: Testosterone kits sold (Kit 1 + Kit 3) | B38: =B6+B8 -> 8 | C38: =C6+C8 -> 17 | D38: =D6+D8 -> 26 | E38: =E6+E8 -> 34 | F38: =F6+F8 -> 40 | G38: =G6+G8 -> 48 | H38: =SUM(B38:G38) -> 173
A39: Low-T results (35%) | B39: =ROUND(B38*Assumptions!B24,0) -> 3 | C39: =ROUND(C38*Assumptions!B24,0) -> 6 | D39: =ROUND(D38*Assumptions!B24,0) -> 9 | E39: =ROUND(E38*Assumptions!B24,0) -> 12 | F39: =ROUND(F38*Assumptions!B24,0) -> 14 | G39: =ROUND(G38*Assumptions!B24,0) -> 17 | H39: =SUM(B39:G39) -> 61
A40: Deposits secured (50% of low-T) | B40: =ROUND(B39*Assumptions!B25,0) -> 2 | C40: =ROUND(C39*Assumptions!B25,0) -> 3 | D40: =ROUND(D39*Assumptions!B25,0) -> 5 | E40: =ROUND(E39*Assumptions!B25,0) -> 6 | F40: =ROUND(F39*Assumptions!B25,0) -> 7 | G40: =ROUND(G39*Assumptions!B25,0) -> 9 | H40: =SUM(B40:G40) -> 32
A41: Deposit Revenue | B41: =B40*Assumptions!B23 -> 150 | C41: =C40*Assumptions!B23 -> 225 | D41: =D40*Assumptions!B23 -> 375 | E41: =E40*Assumptions!B23 -> 450 | F41: =F40*Assumptions!B23 -> 525 | G41: =G40*Assumptions!B23 -> 675 | H41: =SUM(B41:G41) -> 2400
A43: TOTAL REVENUE
A44: Kit Revenue | B44: =B16 -> 2197 | C44: =C16 -> 3991 | D44: =D16 -> 5764 | E44: =E16 -> 7211 | F44: =F16 -> 8420 | G44: =G16 -> 9807 | H44: =H16 -> 37390
A45: Supplement Revenue | B45: =B33 -> 69.9 | C45: =C33 -> 174.75 | D45: =D33 -> 349.5 | E45: =E33 -> 559.2 | F45: =F33 -> 803.85 | G45: =G33 -> 1048.5 | H45: =H33 -> 3005.7
A46: Deposit Revenue | B46: =B41 -> 150 | C46: =C41 -> 225 | D46: =D41 -> 375 | E46: =E41 -> 450 | F46: =F41 -> 525 | G46: =G41 -> 675 | H46: =H41 -> 2400
A47: TOTAL REVENUE | B47: =B44+B45+B46 -> 2416.9 | C47: =C44+C45+C46 -> 4390.75 | D47: =D44+D45+D46 -> 6488.5 | E47: =E44+E45+E46 -> 8220.2 | F47: =F44+F45+F46 -> 9748.85 | G47: =G44+G45+G46 -> 11530.5 | H47: =H44+H45+H46 -> 42795.7
A49: TOTAL COGS
...
